<?xml version="1.0" ?>
<robot name="bionic_biped_robot" xmlns:xacro="http://www.ros.org/wiki/xacro">

<xacro:include filename="$(find bionic_biped_robot_description)/urdf/materials.xacro" />
<xacro:include filename="$(find bionic_biped_robot_description)/urdf/bionic_biped_robot.trans" />
<link name="base_link">
  <inertial>
    <origin xyz="-0.029060836065414125 0.0002496064887810068 0.009364201848387986" rpy="0 0 0"/>
    <mass value="0.42566063723793834"/>
    <inertia ixx="0.000885" iyy="0.000452" izz="0.000847" ixy="3.1e-05" iyz="1e-06" ixz="-7e-06"/>
  </inertial>
  <visual>
    <origin xyz="0 0 0" rpy="0 0 0"/>
    <geometry>
      <mesh filename="package://bionic_biped_robot_description/meshes/base_link.stl" scale="0.001 0.001 0.001"/>
    </geometry>
    <material name="pa_11_nylon_hp_1130_eos_p_396_3d_"/>
  </visual>
  <collision>
    <origin xyz="0 0 0" rpy="0 0 0"/>
    <geometry>
      <mesh filename="package://bionic_biped_robot_description/meshes/base_link.stl" scale="0.001 0.001 0.001"/>
    </geometry>
  </collision>
</link>

<link name="R_hip_roll_xl_2">
  <inertial>
    <origin xyz="-0.004986969075831562 -0.014720577155303775 -0.015884992551365343" rpy="0 0 0"/>
    <mass value="0.040973661549071165"/>
    <inertia ixx="1e-05" iyy="1.1e-05" izz="6e-06" ixy="-0.0" iyz="-0.0" ixz="0.0"/>
  </inertial>
  <visual>
    <origin xyz="0.015186 0.058805 -0.032787" rpy="0 0 0"/>
    <geometry>
      <mesh filename="package://bionic_biped_robot_description/meshes/R_hip_roll_xl_2.stl" scale="0.001 0.001 0.001"/>
    </geometry>
    <material name=""/>
  </visual>
  <collision>
    <origin xyz="0.015186 0.058805 -0.032787" rpy="0 0 0"/>
    <geometry>
      <mesh filename="package://bionic_biped_robot_description/meshes/R_hip_roll_xl_2.stl" scale="0.001 0.001 0.001"/>
    </geometry>
  </collision>
</link>

<link name="R_hip_roll_2">
  <inertial>
    <origin xyz="0.01663231339614729 0.001207315463769884 0.0006989681967823" rpy="0 0 0"/>
    <mass value="0.001436423594975712"/>
    <inertia ixx="0.0" iyy="0.0" izz="0.0" ixy="-0.0" iyz="-0.0" ixz="-0.0"/>
  </inertial>
  <visual>
    <origin xyz="0.036253 0.074726 -0.004173" rpy="0 0 0"/>
    <geometry>
      <mesh filename="package://bionic_biped_robot_description/meshes/R_hip_roll_2.stl" scale="0.001 0.001 0.001"/>
    </geometry>
    <material name=""/>
  </visual>
  <collision>
    <origin xyz="0.036253 0.074726 -0.004173" rpy="0 0 0"/>
    <geometry>
      <mesh filename="package://bionic_biped_robot_description/meshes/R_hip_roll_2.stl" scale="0.001 0.001 0.001"/>
    </geometry>
  </collision>
</link>

<link name="hip_roll_bracket_1">
  <inertial>
    <origin xyz="-0.005977280037243966 -0.0004319145967555671 -0.00017857921335133736" rpy="0 0 0"/>
    <mass value="0.005303897131480488"/>
    <inertia ixx="1e-06" iyy="1e-06" izz="1e-06" ixy="0.0" iyz="0.0" ixz="0.0"/>
  </inertial>
  <visual>
    <origin xyz="0.038247 0.07487 -0.004114" rpy="0 0 0"/>
    <geometry>
      <mesh filename="package://bionic_biped_robot_description/meshes/hip_roll_bracket_1.stl" scale="0.001 0.001 0.001"/>
    </geometry>
    <material name="pa_11_nylon_hp_1130_eos_p_396_3d_"/>
  </visual>
  <collision>
    <origin xyz="0.038247 0.07487 -0.004114" rpy="0 0 0"/>
    <geometry>
      <mesh filename="package://bionic_biped_robot_description/meshes/hip_roll_bracket_1.stl" scale="0.001 0.001 0.001"/>
    </geometry>
  </collision>
</link>

<link name="R_hip_yaw_xl_2">
  <inertial>
    <origin xyz="-0.00699837936059209 -0.014828178635805975 -0.006687919117201799" rpy="0 0 0"/>
    <mass value="0.040973661549071165"/>
    <inertia ixx="6e-06" iyy="1.1e-05" izz="1e-05" ixy="-0.0" iyz="-0.0" ixz="-0.0"/>
  </inertial>
  <visual>
    <origin xyz="0.056649 0.061888 -0.00954" rpy="0 0 0"/>
    <geometry>
      <mesh filename="package://bionic_biped_robot_description/meshes/R_hip_yaw_xl_2.stl" scale="0.001 0.001 0.001"/>
    </geometry>
    <material name=""/>
  </visual>
  <collision>
    <origin xyz="0.056649 0.061888 -0.00954" rpy="0 0 0"/>
    <geometry>
      <mesh filename="package://bionic_biped_robot_description/meshes/R_hip_yaw_xl_2.stl" scale="0.001 0.001 0.001"/>
    </geometry>
  </collision>
</link>

<link name="R_hip_yaw_2">
  <inertial>
    <origin xyz="-0.0007017293152988338 2.2652475475268274e-05 0.016676361625966155" rpy="0 0 0"/>
    <mass value="0.001436423594975712"/>
    <inertia ixx="0.0" iyy="0.0" izz="0.0" ixy="0.0" iyz="-0.0" ixz="0.0"/>
  </inertial>
  <visual>
    <origin xyz="0.050948 0.075856 0.013273" rpy="0 0 0"/>
    <geometry>
      <mesh filename="package://bionic_biped_robot_description/meshes/R_hip_yaw_2.stl" scale="0.001 0.001 0.001"/>
    </geometry>
    <material name=""/>
  </visual>
  <collision>
    <origin xyz="0.050948 0.075856 0.013273" rpy="0 0 0"/>
    <geometry>
      <mesh filename="package://bionic_biped_robot_description/meshes/R_hip_yaw_2.stl" scale="0.001 0.001 0.001"/>
    </geometry>
  </collision>
</link>

<link name="hip_yaw_bracket_1">
  <inertial>
    <origin xyz="-0.0018463725124446412 -0.0001554031109584353 -0.005509867635975271" rpy="0 0 0"/>
    <mass value="0.0070036931272659"/>
    <inertia ixx="1e-06" iyy="1e-06" izz="2e-06" ixy="-0.0" iyz="-0.0" ixz="-0.0"/>
  </inertial>
  <visual>
    <origin xyz="0.050888 0.07586 0.015272" rpy="0 0 0"/>
    <geometry>
      <mesh filename="package://bionic_biped_robot_description/meshes/hip_yaw_bracket_1.stl" scale="0.001 0.001 0.001"/>
    </geometry>
    <material name="pa_11_nylon_hp_1130_eos_p_396_3d_"/>
  </visual>
  <collision>
    <origin xyz="0.050888 0.07586 0.015272" rpy="0 0 0"/>
    <geometry>
      <mesh filename="package://bionic_biped_robot_description/meshes/hip_yaw_bracket_1.stl" scale="0.001 0.001 0.001"/>
    </geometry>
  </collision>
</link>

<link name="R_hip_pitch_xl_2">
  <inertial>
    <origin xyz="-0.0034399795138700118 -0.005842710871260232 -0.02087660696885252" rpy="0 0 0"/>
    <mass value="0.040973661549071165"/>
    <inertia ixx="1e-05" iyy="1e-05" izz="8e-06" ixy="-0.0" iyz="0.0" ixz="2e-06"/>
  </inertial>
  <visual>
    <origin xyz="0.031688 0.068484 0.020992" rpy="0 0 0"/>
    <geometry>
      <mesh filename="package://bionic_biped_robot_description/meshes/R_hip_pitch_xl_2.stl" scale="0.001 0.001 0.001"/>
    </geometry>
    <material name=""/>
  </visual>
  <collision>
    <origin xyz="0.031688 0.068484 0.020992" rpy="0 0 0"/>
    <geometry>
      <mesh filename="package://bionic_biped_robot_description/meshes/R_hip_pitch_xl_2.stl" scale="0.001 0.001 0.001"/>
    </geometry>
  </collision>
</link>

<link name="R_hip_pitch_2">
  <inertial>
    <origin xyz="0.0010989591782883945 -0.016652782330582303 0.00024228339881331856" rpy="0 0 0"/>
    <mass value="0.001436423594975712"/>
    <inertia ixx="0.0" iyy="0.0" izz="0.0" ixy="0.0" iyz="0.0" ixz="-0.0"/>
  </inertial>
  <visual>
    <origin xyz="0.029885 0.057452 0.052346" rpy="0 0 0"/>
    <geometry>
      <mesh filename="package://bionic_biped_robot_description/meshes/R_hip_pitch_2.stl" scale="0.001 0.001 0.001"/>
    </geometry>
    <material name=""/>
  </visual>
  <collision>
    <origin xyz="0.029885 0.057452 0.052346" rpy="0 0 0"/>
    <geometry>
      <mesh filename="package://bionic_biped_robot_description/meshes/R_hip_pitch_2.stl" scale="0.001 0.001 0.001"/>
    </geometry>
  </collision>
</link>

<link name="hip_pitch_bracket_1">
  <inertial>
    <origin xyz="0.007539456611218846 -0.018546343314648363 -0.009937230800389683" rpy="0 0 0"/>
    <mass value="0.005694190208798132"/>
    <inertia ixx="2e-06" iyy="1e-06" izz="2e-06" ixy="0.0" iyz="0.0" ixz="0.0"/>
  </inertial>
  <visual>
    <origin xyz="0.030029 0.055457 0.052355" rpy="0 0 0"/>
    <geometry>
      <mesh filename="package://bionic_biped_robot_description/meshes/hip_pitch_bracket_1.stl" scale="0.001 0.001 0.001"/>
    </geometry>
    <material name="pa_11_nylon_hp_1130_eos_p_396_3d_"/>
  </visual>
  <collision>
    <origin xyz="0.030029 0.055457 0.052355" rpy="0 0 0"/>
    <geometry>
      <mesh filename="package://bionic_biped_robot_description/meshes/hip_pitch_bracket_1.stl" scale="0.001 0.001 0.001"/>
    </geometry>
  </collision>
</link>

<link name="R_knee_xl_2">
  <inertial>
    <origin xyz="0.005664421967444319 -0.005198050482948566 -0.02376056540835883" rpy="0 0 0"/>
    <mass value="0.040973661549071165"/>
    <inertia ixx="1e-05" iyy="1e-05" izz="8e-06" ixy="-0.0" iyz="0.0" ixz="2e-06"/>
  </inertial>
  <visual>
    <origin xyz="0.011949 0.067239 0.0649" rpy="0 0 0"/>
    <geometry>
      <mesh filename="package://bionic_biped_robot_description/meshes/R_knee_xl_2.stl" scale="0.001 0.001 0.001"/>
    </geometry>
    <material name=""/>
  </visual>
  <collision>
    <origin xyz="0.011949 0.067239 0.0649" rpy="0 0 0"/>
    <geometry>
      <mesh filename="package://bionic_biped_robot_description/meshes/R_knee_xl_2.stl" scale="0.001 0.001 0.001"/>
    </geometry>
  </collision>
</link>

<link name="R_knee_2">
  <inertial>
    <origin xyz="0.0010983606596026325 -0.01665312194227056 0.00024232495930738562" rpy="0 0 0"/>
    <mass value="0.001436423594975712"/>
    <inertia ixx="0.0" iyy="0.0" izz="0.0" ixy="0.0" iyz="0.0" ixz="-0.0"/>
  </inertial>
  <visual>
    <origin xyz="0.001041 0.055562 0.099138" rpy="0 0 0"/>
    <geometry>
      <mesh filename="package://bionic_biped_robot_description/meshes/R_knee_2.stl" scale="0.001 0.001 0.001"/>
    </geometry>
    <material name=""/>
  </visual>
  <collision>
    <origin xyz="0.001041 0.055562 0.099138" rpy="0 0 0"/>
    <geometry>
      <mesh filename="package://bionic_biped_robot_description/meshes/R_knee_2.stl" scale="0.001 0.001 0.001"/>
    </geometry>
  </collision>
</link>

<link name="knee_r_brecket_1">
  <inertial>
    <origin xyz="0.009879615617338428 -0.007544867889285538 -0.023592524067663698" rpy="0 0 0"/>
    <mass value="0.00786109169007575"/>
    <inertia ixx="1e-06" iyy="1e-06" izz="1e-06" ixy="0.0" iyz="-0.0" ixz="0.0"/>
  </inertial>
  <visual>
    <origin xyz="0.001185 0.053567 0.099146" rpy="0 0 0"/>
    <geometry>
      <mesh filename="package://bionic_biped_robot_description/meshes/knee_r_brecket_1.stl" scale="0.001 0.001 0.001"/>
    </geometry>
    <material name="pa_11_nylon_hp_1130_eos_p_396_3d_"/>
  </visual>
  <collision>
    <origin xyz="0.001185 0.053567 0.099146" rpy="0 0 0"/>
    <geometry>
      <mesh filename="package://bionic_biped_robot_description/meshes/knee_r_brecket_1.stl" scale="0.001 0.001 0.001"/>
    </geometry>
  </collision>
</link>

<link name="leg_upper_1">
  <inertial>
    <origin xyz="-0.023627209371366004 -0.0018812413574959413 -0.04402500093082774" rpy="0 0 0"/>
    <mass value="0.012719491840295135"/>
    <inertia ixx="8e-06" iyy="1.1e-05" izz="3e-06" ixy="-0.0" iyz="-0.0" ixz="-4e-06"/>
  </inertial>
  <visual>
    <origin xyz="-0.011989 0.065254 0.124731" rpy="0 0 0"/>
    <geometry>
      <mesh filename="package://bionic_biped_robot_description/meshes/leg_upper_1.stl" scale="0.001 0.001 0.001"/>
    </geometry>
    <material name="pa_11_nylon_hp_1130_eos_p_396_3d_"/>
  </visual>
  <collision>
    <origin xyz="-0.011989 0.065254 0.124731" rpy="0 0 0"/>
    <geometry>
      <mesh filename="package://bionic_biped_robot_description/meshes/leg_upper_1.stl" scale="0.001 0.001 0.001"/>
    </geometry>
  </collision>
</link>

<link name="lower_knee_link_2">
  <inertial>
    <origin xyz="0.005339367105491769 0.0003737553050349868 -0.003361608401626831" rpy="0 0 0"/>
    <mass value="0.010036812614450108"/>
    <inertia ixx="1e-06" iyy="2e-06" izz="1e-06" ixy="-0.0" iyz="0.0" ixz="0.0"/>
  </inertial>
  <visual>
    <origin xyz="0.035265 0.069017 0.212781" rpy="0 0 0"/>
    <geometry>
      <mesh filename="package://bionic_biped_robot_description/meshes/lower_knee_link_2.stl" scale="0.001 0.001 0.001"/>
    </geometry>
    <material name="pa_11_nylon_hp_1130_eos_p_396_3d_"/>
  </visual>
  <collision>
    <origin xyz="0.035265 0.069017 0.212781" rpy="0 0 0"/>
    <geometry>
      <mesh filename="package://bionic_biped_robot_description/meshes/lower_knee_link_2.stl" scale="0.001 0.001 0.001"/>
    </geometry>
  </collision>
</link>

<link name="R_ankle_xl_2">
  <inertial>
    <origin xyz="0.0023780861009838963 -0.14124865844405804 -0.013927734264633257" rpy="0 0 0"/>
    <mass value="0.040973661549071165"/>
    <inertia ixx="1e-05" iyy="1e-05" izz="8e-06" ixy="-0.0" iyz="0.0" ixz="2e-06"/>
  </inertial>
  <visual>
    <origin xyz="0.017665 -0.073986 0.225119" rpy="0 0 0"/>
    <geometry>
      <mesh filename="package://bionic_biped_robot_description/meshes/R_ankle_xl_2.stl" scale="0.001 0.001 0.001"/>
    </geometry>
    <material name=""/>
  </visual>
  <collision>
    <origin xyz="0.017665 -0.073986 0.225119" rpy="0 0 0"/>
    <geometry>
      <mesh filename="package://bionic_biped_robot_description/meshes/R_ankle_xl_2.stl" scale="0.001 0.001 0.001"/>
    </geometry>
  </collision>
</link>

<link name="R_ankle_2">
  <inertial>
    <origin xyz="0.0013009380681431246 -0.016640129255585098 -0.00010806382592756791" rpy="0 0 0"/>
    <mass value="0.001436423594975712"/>
    <inertia ixx="0.0" iyy="0.0" izz="0.0" ixy="0.0" iyz="-0.0" ixz="0.0"/>
  </inertial>
  <visual>
    <origin xyz="0.022902 0.05123 0.228702" rpy="0 0 0"/>
    <geometry>
      <mesh filename="package://bionic_biped_robot_description/meshes/R_ankle_2.stl" scale="0.001 0.001 0.001"/>
    </geometry>
    <material name=""/>
  </visual>
  <collision>
    <origin xyz="0.022902 0.05123 0.228702" rpy="0 0 0"/>
    <geometry>
      <mesh filename="package://bionic_biped_robot_description/meshes/R_ankle_2.stl" scale="0.001 0.001 0.001"/>
    </geometry>
  </collision>
</link>

<link name="ankle_link_1_2">
  <inertial>
    <origin xyz="-0.01961971128153585 -0.009167995860988223 -0.012464484549498916" rpy="0 0 0"/>
    <mass value="0.006084906833817184"/>
    <inertia ixx="1e-06" iyy="1e-06" izz="1e-06" ixy="-0.0" iyz="-0.0" ixz="-0.0"/>
  </inertial>
  <visual>
    <origin xyz="0.023046 0.049236 0.22871" rpy="0 0 0"/>
    <geometry>
      <mesh filename="package://bionic_biped_robot_description/meshes/ankle_link_1_2.stl" scale="0.001 0.001 0.001"/>
    </geometry>
    <material name="pa_11_nylon_hp_1130_eos_p_396_3d_"/>
  </visual>
  <collision>
    <origin xyz="0.023046 0.049236 0.22871" rpy="0 0 0"/>
    <geometry>
      <mesh filename="package://bionic_biped_robot_description/meshes/ankle_link_1_2.stl" scale="0.001 0.001 0.001"/>
    </geometry>
  </collision>
</link>

<link name="ankle_link_2_2">
  <inertial>
    <origin xyz="-0.018515364831153396 0.002677892138265192 -0.011304909272308539" rpy="0 0 0"/>
    <mass value="0.004445165114646534"/>
    <inertia ixx="0.0" iyy="1e-06" izz="1e-06" ixy="0.0" iyz="0.0" ixz="-0.0"/>
  </inertial>
  <visual>
    <origin xyz="0.020314 0.087137 0.228557" rpy="0 0 0"/>
    <geometry>
      <mesh filename="package://bionic_biped_robot_description/meshes/ankle_link_2_2.stl" scale="0.001 0.001 0.001"/>
    </geometry>
    <material name="pa_11_nylon_hp_1130_eos_p_396_3d_"/>
  </visual>
  <collision>
    <origin xyz="0.020314 0.087137 0.228557" rpy="0 0 0"/>
    <geometry>
      <mesh filename="package://bionic_biped_robot_description/meshes/ankle_link_2_2.stl" scale="0.001 0.001 0.001"/>
    </geometry>
  </collision>
</link>

<link name="R_bionic_biped_robot_ankle_bar_1">
  <inertial>
    <origin xyz="0.031959950767911874 -0.1356965791043112 -0.035255068475129575" rpy="0 0 0"/>
    <mass value="0.003337002701996774"/>
    <inertia ixx="2e-06" iyy="3e-06" izz="1e-06" ixy="-0.0" iyz="0.0" ixz="1e-06"/>
  </inertial>
  <visual>
    <origin xyz="0.057018 -0.067058 0.244955" rpy="0 0 0"/>
    <geometry>
      <mesh filename="package://bionic_biped_robot_description/meshes/R_bionic_biped_robot_ankle_bar_1.stl" scale="0.001 0.001 0.001"/>
    </geometry>
    <material name="pa_11_nylon_hp_1130_eos_p_396_3d_"/>
  </visual>
  <collision>
    <origin xyz="0.057018 -0.067058 0.244955" rpy="0 0 0"/>
    <geometry>
      <mesh filename="package://bionic_biped_robot_description/meshes/R_bionic_biped_robot_ankle_bar_1.stl" scale="0.001 0.001 0.001"/>
    </geometry>
  </collision>
</link>

<link name="R_ankle_bar_parts_1">
  <inertial>
    <origin xyz="0.00014428021092786425 -0.001994497521576738 8.022236874460908e-06" rpy="0 0 0"/>
    <mass value="0.0001072728227494817"/>
    <inertia ixx="0.0" iyy="0.0" izz="0.0" ixy="-0.0" iyz="-0.0" ixz="0.0"/>
  </inertial>
  <visual>
    <origin xyz="-0.003742 0.064746 0.327174" rpy="0 0 0"/>
    <geometry>
      <mesh filename="package://bionic_biped_robot_description/meshes/R_ankle_bar_parts_1.stl" scale="0.001 0.001 0.001"/>
    </geometry>
    <material name="_"/>
  </visual>
  <collision>
    <origin xyz="-0.003742 0.064746 0.327174" rpy="0 0 0"/>
    <geometry>
      <mesh filename="package://bionic_biped_robot_description/meshes/R_ankle_bar_parts_1.stl" scale="0.001 0.001 0.001"/>
    </geometry>
  </collision>
</link>

<link name="lower_link_1">
  <inertial>
    <origin xyz="-0.0064653639832924275 -0.006542113788295889 -0.015891072697331005" rpy="0 0 0"/>
    <mass value="0.008544769707383056"/>
    <inertia ixx="1e-06" iyy="1e-06" izz="1e-06" ixy="-0.0" iyz="-0.0" ixz="-0.0"/>
  </inertial>
  <visual>
    <origin xyz="-0.004663 0.060338 0.24499" rpy="0 0 0"/>
    <geometry>
      <mesh filename="package://bionic_biped_robot_description/meshes/lower_link_1.stl" scale="0.001 0.001 0.001"/>
    </geometry>
    <material name="pa_11_nylon_hp_1130_eos_p_396_3d_"/>
  </visual>
  <collision>
    <origin xyz="-0.004663 0.060338 0.24499" rpy="0 0 0"/>
    <geometry>
      <mesh filename="package://bionic_biped_robot_description/meshes/lower_link_1.stl" scale="0.001 0.001 0.001"/>
    </geometry>
  </collision>
</link>

<link name="leg_lower_2">
  <inertial>
    <origin xyz="0.016577282937612937 0.0010941529441703401 -0.024991797663463378" rpy="0 0 0"/>
    <mass value="0.007702697584770665"/>
    <inertia ixx="2e-06" iyy="2e-06" izz="1e-06" ixy="-0.0" iyz="0.0" ixz="1e-06"/>
  </inertial>
  <visual>
    <origin xyz="0.001098 0.066806 0.262026" rpy="0 0 0"/>
    <geometry>
      <mesh filename="package://bionic_biped_robot_description/meshes/leg_lower_2.stl" scale="0.001 0.001 0.001"/>
    </geometry>
    <material name="pa_11_nylon_hp_1130_eos_p_396_3d_"/>
  </visual>
  <collision>
    <origin xyz="0.001098 0.066806 0.262026" rpy="0 0 0"/>
    <geometry>
      <mesh filename="package://bionic_biped_robot_description/meshes/leg_lower_2.stl" scale="0.001 0.001 0.001"/>
    </geometry>
  </collision>
</link>

<link name="shaft_1">
  <inertial>
    <origin xyz="0.011021198643625819 -0.14106897092774662 0.001096999932918341" rpy="0 0 0"/>
    <mass value="5.79273242847201e-05"/>
    <inertia ixx="0.0" iyy="0.0" izz="0.0" ixy="0.0" iyz="0.0" ixz="-0.0"/>
  </inertial>
  <visual>
    <origin xyz="-0.018621 -0.076285 0.311091" rpy="0 0 0"/>
    <geometry>
      <mesh filename="package://bionic_biped_robot_description/meshes/shaft_1.stl" scale="0.001 0.001 0.001"/>
    </geometry>
    <material name=""/>
  </visual>
  <collision>
    <origin xyz="-0.018621 -0.076285 0.311091" rpy="0 0 0"/>
    <geometry>
      <mesh filename="package://bionic_biped_robot_description/meshes/shaft_1.stl" scale="0.001 0.001 0.001"/>
    </geometry>
  </collision>
</link>

<link name="foot_1">
  <inertial>
    <origin xyz="0.012733500599400645 -0.00610941412659672 -0.002202016875568147" rpy="0 0 0"/>
    <mass value="0.009360295877442892"/>
    <inertia ixx="1e-06" iyy="3e-06" izz="2e-06" ixy="-0.0" iyz="-0.0" ixz="-1e-06"/>
  </inertial>
  <visual>
    <origin xyz="-0.029139 0.057802 0.310022" rpy="0 0 0"/>
    <geometry>
      <mesh filename="package://bionic_biped_robot_description/meshes/foot_1.stl" scale="0.001 0.001 0.001"/>
    </geometry>
    <material name="pa_11_nylon_hp_1130_eos_p_396_3d_"/>
  </visual>
  <collision>
    <origin xyz="-0.029139 0.057802 0.310022" rpy="0 0 0"/>
    <geometry>
      <mesh filename="package://bionic_biped_robot_description/meshes/foot_1.stl" scale="0.001 0.001 0.001"/>
    </geometry>
  </collision>
</link>

<link name="L_hip_roll_xl_2">
  <inertial>
    <origin xyz="-0.007035358994863367 0.013704923001309606 -0.016000610474206135" rpy="0 0 0"/>
    <mass value="0.040973661549071165"/>
    <inertia ixx="1e-05" iyy="1.1e-05" izz="6e-06" ixy="-0.0" iyz="-0.0" ixz="0.0"/>
  </inertial>
  <visual>
    <origin xyz="0.023814 -0.060884 -0.032303" rpy="0 0 0"/>
    <geometry>
      <mesh filename="package://bionic_biped_robot_description/meshes/L_hip_roll_xl_2.stl" scale="0.001 0.001 0.001"/>
    </geometry>
    <material name=""/>
  </visual>
  <collision>
    <origin xyz="0.023814 -0.060884 -0.032303" rpy="0 0 0"/>
    <geometry>
      <mesh filename="package://bionic_biped_robot_description/meshes/L_hip_roll_xl_2.stl" scale="0.001 0.001 0.001"/>
    </geometry>
  </collision>
</link>

<link name="L_hip_roll_2">
  <inertial>
    <origin xyz="0.01663292347711554 0.0012078156203833013 0.0006983502739413925" rpy="0 0 0"/>
    <mass value="0.001436423594975712"/>
    <inertia ixx="0.0" iyy="0.0" izz="0.0" ixy="-0.0" iyz="-0.0" ixz="-0.0"/>
  </inertial>
  <visual>
    <origin xyz="0.04693 -0.073388 -0.003574" rpy="0 0 0"/>
    <geometry>
      <mesh filename="package://bionic_biped_robot_description/meshes/L_hip_roll_2.stl" scale="0.001 0.001 0.001"/>
    </geometry>
    <material name=""/>
  </visual>
  <collision>
    <origin xyz="0.04693 -0.073388 -0.003574" rpy="0 0 0"/>
    <geometry>
      <mesh filename="package://bionic_biped_robot_description/meshes/L_hip_roll_2.stl" scale="0.001 0.001 0.001"/>
    </geometry>
  </collision>
</link>

<link name="hip_roll_bracket_2">
  <inertial>
    <origin xyz="-0.005977669956275557 -0.000431414440142025 -0.000178197136192256" rpy="0 0 0"/>
    <mass value="0.005303897131480488"/>
    <inertia ixx="1e-06" iyy="1e-06" izz="1e-06" ixy="0.0" iyz="0.0" ixz="0.0"/>
  </inertial>
  <visual>
    <origin xyz="0.048923 -0.073244 -0.003514" rpy="0 0 0"/>
    <geometry>
      <mesh filename="package://bionic_biped_robot_description/meshes/hip_roll_bracket_2.stl" scale="0.001 0.001 0.001"/>
    </geometry>
    <material name="pa_11_nylon_hp_1130_eos_p_396_3d_"/>
  </visual>
  <collision>
    <origin xyz="0.048923 -0.073244 -0.003514" rpy="0 0 0"/>
    <geometry>
      <mesh filename="package://bionic_biped_robot_description/meshes/hip_roll_bracket_2.stl" scale="0.001 0.001 0.001"/>
    </geometry>
  </collision>
</link>

<link name="L_hip_yow_xl_2">
  <inertial>
    <origin xyz="-0.01972376927962364 0.16171232152080728 -0.007402537040042885" rpy="0 0 0"/>
    <mass value="0.040973661549071165"/>
    <inertia ixx="6e-06" iyy="1.1e-05" izz="1e-05" ixy="-0.0" iyz="-0.0" ixz="-0.0"/>
  </inertial>
  <visual>
    <origin xyz="0.0546 0.090314 -0.009655" rpy="0 0 0"/>
    <geometry>
      <mesh filename="package://bionic_biped_robot_description/meshes/L_hip_yow_xl_2.stl" scale="0.001 0.001 0.001"/>
    </geometry>
    <material name=""/>
  </visual>
  <collision>
    <origin xyz="0.0546 0.090314 -0.009655" rpy="0 0 0"/>
    <geometry>
      <mesh filename="package://bionic_biped_robot_description/meshes/L_hip_yow_xl_2.stl" scale="0.001 0.001 0.001"/>
    </geometry>
  </collision>
</link>

<link name="L_hip_yow_2">
  <inertial>
    <origin xyz="-0.0007021192343301744 2.31526320890324e-05 0.016675743703124895" rpy="0 0 0"/>
    <mass value="0.001436423594975712"/>
    <inertia ixx="0.0" iyy="0.0" izz="0.0" ixy="0.0" iyz="-0.0" ixz="0.0"/>
  </inertial>
  <visual>
    <origin xyz="0.061624 -0.072258 0.013872" rpy="0 0 0"/>
    <geometry>
      <mesh filename="package://bionic_biped_robot_description/meshes/L_hip_yow_2.stl" scale="0.001 0.001 0.001"/>
    </geometry>
    <material name=""/>
  </visual>
  <collision>
    <origin xyz="0.061624 -0.072258 0.013872" rpy="0 0 0"/>
    <geometry>
      <mesh filename="package://bionic_biped_robot_description/meshes/L_hip_yow_2.stl" scale="0.001 0.001 0.001"/>
    </geometry>
  </collision>
</link>

<link name="hip_yaw_bracket_2">
  <inertial>
    <origin xyz="-0.0018467624314757111 -0.00015590295434435297 -0.005510485558816482" rpy="0 0 0"/>
    <mass value="0.0070036931272659"/>
    <inertia ixx="1e-06" iyy="1e-06" izz="2e-06" ixy="-0.0" iyz="-0.0" ixz="-0.0"/>
  </inertial>
  <visual>
    <origin xyz="0.061564 -0.072255 0.015871" rpy="0 0 0"/>
    <geometry>
      <mesh filename="package://bionic_biped_robot_description/meshes/hip_yaw_bracket_2.stl" scale="0.001 0.001 0.001"/>
    </geometry>
    <material name="pa_11_nylon_hp_1130_eos_p_396_3d_"/>
  </visual>
  <collision>
    <origin xyz="0.061564 -0.072255 0.015871" rpy="0 0 0"/>
    <geometry>
      <mesh filename="package://bionic_biped_robot_description/meshes/hip_yaw_bracket_2.stl" scale="0.001 0.001 0.001"/>
    </geometry>
  </collision>
</link>

<link name="L_hip_pitch_xl_2">
  <inertial>
    <origin xyz="-0.014890326953640929 0.15323635688222426 -0.02151086042531752" rpy="0 0 0"/>
    <mass value="0.040973661549071165"/>
    <inertia ixx="1e-05" iyy="1e-05" izz="8e-06" ixy="-0.0" iyz="0.0" ixz="2e-06"/>
  </inertial>
  <visual>
    <origin xyz="0.030825 0.080452 0.020943" rpy="0 0 0"/>
    <geometry>
      <mesh filename="package://bionic_biped_robot_description/meshes/L_hip_pitch_xl_2.stl" scale="0.001 0.001 0.001"/>
    </geometry>
    <material name=""/>
  </visual>
  <collision>
    <origin xyz="0.030825 0.080452 0.020943" rpy="0 0 0"/>
    <geometry>
      <mesh filename="package://bionic_biped_robot_description/meshes/L_hip_pitch_xl_2.stl" scale="0.001 0.001 0.001"/>
    </geometry>
  </collision>
</link>

<link name="L_hip_pitch_2">
  <inertial>
    <origin xyz="-0.0013108933396089942 0.01663883507412956 0.00010192141907762464" rpy="0 0 0"/>
    <mass value="0.001436423594975712"/>
    <inertia ixx="0.0" iyy="0.0" izz="0.0" ixy="0.0" iyz="-0.0" ixz="0.0"/>
  </inertial>
  <visual>
    <origin xyz="0.038117 -0.056751 0.052809" rpy="0 0 0"/>
    <geometry>
      <mesh filename="package://bionic_biped_robot_description/meshes/L_hip_pitch_2.stl" scale="0.001 0.001 0.001"/>
    </geometry>
    <material name=""/>
  </visual>
  <collision>
    <origin xyz="0.038117 -0.056751 0.052809" rpy="0 0 0"/>
    <geometry>
      <mesh filename="package://bionic_biped_robot_description/meshes/L_hip_pitch_2.stl" scale="0.001 0.001 0.001"/>
    </geometry>
  </collision>
</link>

<link name="hip_pitch_bracket_2">
  <inertial>
    <origin xyz="0.0048070666921878405 0.019355156841966065 -0.010090848723229504" rpy="0 0 0"/>
    <mass value="0.005694190208798132"/>
    <inertia ixx="2e-06" iyy="1e-06" izz="2e-06" ixy="0.0" iyz="0.0" ixz="0.0"/>
  </inertial>
  <visual>
    <origin xyz="0.037973 -0.054756 0.052801" rpy="0 0 0"/>
    <geometry>
      <mesh filename="package://bionic_biped_robot_description/meshes/hip_pitch_bracket_2.stl" scale="0.001 0.001 0.001"/>
    </geometry>
    <material name="pa_11_nylon_hp_1130_eos_p_396_3d_"/>
  </visual>
  <collision>
    <origin xyz="0.037973 -0.054756 0.052801" rpy="0 0 0"/>
    <geometry>
      <mesh filename="package://bionic_biped_robot_description/meshes/hip_pitch_bracket_2.stl" scale="0.001 0.001 0.001"/>
    </geometry>
  </collision>
</link>

<link name="L_knee_xl_2">
  <inertial>
    <origin xyz="-0.005784925472326147 0.15388101727053538 -0.024393818864822753" rpy="0 0 0"/>
    <mass value="0.040973661549071165"/>
    <inertia ixx="1e-05" iyy="1e-05" izz="8e-06" ixy="-0.0" iyz="0.0" ixz="2e-06"/>
  </inertial>
  <visual>
    <origin xyz="0.011087 0.079207 0.064852" rpy="0 0 0"/>
    <geometry>
      <mesh filename="package://bionic_biped_robot_description/meshes/L_knee_xl_2.stl" scale="0.001 0.001 0.001"/>
    </geometry>
    <material name=""/>
  </visual>
  <collision>
    <origin xyz="0.011087 0.079207 0.064852" rpy="0 0 0"/>
    <geometry>
      <mesh filename="package://bionic_biped_robot_description/meshes/L_knee_xl_2.stl" scale="0.001 0.001 0.001"/>
    </geometry>
  </collision>
</link>

<link name="L_knee_2">
  <inertial>
    <origin xyz="-0.001311491858294345 0.016638495462440908 0.00010196297957255906" rpy="0 0 0"/>
    <mass value="0.001436423594975712"/>
    <inertia ixx="0.0" iyy="0.0" izz="0.0" ixy="0.0" iyz="-0.0" ixz="0.0"/>
  </inertial>
  <visual>
    <origin xyz="0.009273 -0.058641 0.099601" rpy="0 0 0"/>
    <geometry>
      <mesh filename="package://bionic_biped_robot_description/meshes/L_knee_2.stl" scale="0.001 0.001 0.001"/>
    </geometry>
    <material name=""/>
  </visual>
  <collision>
    <origin xyz="0.009273 -0.058641 0.099601" rpy="0 0 0"/>
    <geometry>
      <mesh filename="package://bionic_biped_robot_description/meshes/L_knee_2.stl" scale="0.001 0.001 0.001"/>
    </geometry>
  </collision>
</link>

<link name="knee_l_bracket_1">
  <inertial>
    <origin xyz="0.008709796933786283 0.008692816618159599 -0.023657439489187984" rpy="0 0 0"/>
    <mass value="0.007861091690075749"/>
    <inertia ixx="1e-06" iyy="1e-06" izz="1e-06" ixy="-0.0" iyz="0.0" ixz="0.0"/>
  </inertial>
  <visual>
    <origin xyz="0.00913 -0.056646 0.099593" rpy="0 0 0"/>
    <geometry>
      <mesh filename="package://bionic_biped_robot_description/meshes/knee_l_bracket_1.stl" scale="0.001 0.001 0.001"/>
    </geometry>
    <material name="pa_11_nylon_hp_1130_eos_p_396_3d_"/>
  </visual>
  <collision>
    <origin xyz="0.00913 -0.056646 0.099593" rpy="0 0 0"/>
    <geometry>
      <mesh filename="package://bionic_biped_robot_description/meshes/knee_l_bracket_1.stl" scale="0.001 0.001 0.001"/>
    </geometry>
  </collision>
</link>

<link name="leg_upper_2">
  <inertial>
    <origin xyz="-0.02362696582947057 -0.001880993739845585 -0.04402512704897532" rpy="0 0 0"/>
    <mass value="0.012719491840295135"/>
    <inertia ixx="8e-06" iyy="1.1e-05" izz="3e-06" ixy="-0.0" iyz="-0.0" ixz="-4e-06"/>
  </inertial>
  <visual>
    <origin xyz="-0.002247 -0.069894 0.125278" rpy="0 0 0"/>
    <geometry>
      <mesh filename="package://bionic_biped_robot_description/meshes/leg_upper_2.stl" scale="0.001 0.001 0.001"/>
    </geometry>
    <material name="pa_11_nylon_hp_1130_eos_p_396_3d_"/>
  </visual>
  <collision>
    <origin xyz="-0.002247 -0.069894 0.125278" rpy="0 0 0"/>
    <geometry>
      <mesh filename="package://bionic_biped_robot_description/meshes/leg_upper_2.stl" scale="0.001 0.001 0.001"/>
    </geometry>
  </collision>
</link>

<link name="lower_knee_link_1">
  <inertial>
    <origin xyz="-0.004402389352612182 0.13552200292268426 -0.00390873451977361" rpy="0 0 0"/>
    <mass value="0.010036812614450108"/>
    <inertia ixx="1e-06" iyy="2e-06" izz="1e-06" ixy="-0.0" iyz="0.0" ixz="0.0"/>
  </inertial>
  <visual>
    <origin xyz="0.035265 0.069017 0.212781" rpy="0 0 0"/>
    <geometry>
      <mesh filename="package://bionic_biped_robot_description/meshes/lower_knee_link_1.stl" scale="0.001 0.001 0.001"/>
    </geometry>
    <material name="pa_11_nylon_hp_1130_eos_p_396_3d_"/>
  </visual>
  <collision>
    <origin xyz="0.035265 0.069017 0.212781" rpy="0 0 0"/>
    <geometry>
      <mesh filename="package://bionic_biped_robot_description/meshes/lower_knee_link_1.stl" scale="0.001 0.001 0.001"/>
    </geometry>
  </collision>
</link>

<link name="L_ankle_xl_2">
  <inertial>
    <origin xyz="-0.008169875243508144 0.004862676860505885 -0.014529090337655204" rpy="0 0 0"/>
    <mass value="0.040973661549071165"/>
    <inertia ixx="1e-05" iyy="1e-05" izz="8e-06" ixy="-0.0" iyz="0.0" ixz="2e-06"/>
  </inertial>
  <visual>
    <origin xyz="0.016803 -0.062017 0.225071" rpy="0 0 0"/>
    <geometry>
      <mesh filename="package://bionic_biped_robot_description/meshes/L_ankle_xl_2.stl" scale="0.001 0.001 0.001"/>
    </geometry>
    <material name=""/>
  </visual>
  <collision>
    <origin xyz="0.016803 -0.062017 0.225071" rpy="0 0 0"/>
    <geometry>
      <mesh filename="package://bionic_biped_robot_description/meshes/L_ankle_xl_2.stl" scale="0.001 0.001 0.001"/>
    </geometry>
  </collision>
</link>

<link name="L_ankle_2">
  <inertial>
    <origin xyz="-0.0010890995168576952 0.016653740939449872 -0.00023643298842213056" rpy="0 0 0"/>
    <mass value="0.001436423594975712"/>
    <inertia ixx="0.0" iyy="0.0" izz="0.0" ixy="0.0" iyz="0.0" ixz="-0.0"/>
  </inertial>
  <visual>
    <origin xyz="0.030199 -0.050006 0.229112" rpy="0 0 0"/>
    <geometry>
      <mesh filename="package://bionic_biped_robot_description/meshes/L_ankle_2.stl" scale="0.001 0.001 0.001"/>
    </geometry>
    <material name=""/>
  </visual>
  <collision>
    <origin xyz="0.030199 -0.050006 0.229112" rpy="0 0 0"/>
    <geometry>
      <mesh filename="package://bionic_biped_robot_description/meshes/L_ankle_2.stl" scale="0.001 0.001 0.001"/>
    </geometry>
  </collision>
</link>

<link name="ankle_link_2_1">
  <inertial>
    <origin xyz="-0.017933107710460243 -0.0053969087618745 -0.01127278504476667" rpy="0 0 0"/>
    <mass value="0.004445165114646534"/>
    <inertia ixx="0.0" iyy="1e-06" izz="1e-06" ixy="-0.0" iyz="-0.0" ixz="-0.0"/>
  </inertial>
  <visual>
    <origin xyz="0.032788 -0.085913 0.229257" rpy="0 0 0"/>
    <geometry>
      <mesh filename="package://bionic_biped_robot_description/meshes/ankle_link_2_1.stl" scale="0.001 0.001 0.001"/>
    </geometry>
    <material name="pa_11_nylon_hp_1130_eos_p_396_3d_"/>
  </visual>
  <collision>
    <origin xyz="0.032788 -0.085913 0.229257" rpy="0 0 0"/>
    <geometry>
      <mesh filename="package://bionic_biped_robot_description/meshes/ankle_link_2_1.stl" scale="0.001 0.001 0.001"/>
    </geometry>
  </collision>
</link>

<link name="ankle_link_1_1">
  <inertial>
    <origin xyz="-0.020724300163594417 0.00615941228503341 -0.012526224080413095" rpy="0 0 0"/>
    <mass value="0.006084906833817184"/>
    <inertia ixx="1e-06" iyy="1e-06" izz="1e-06" ixy="0.0" iyz="0.0" ixz="-0.0"/>
  </inertial>
  <visual>
    <origin xyz="0.030056 -0.048011 0.229104" rpy="0 0 0"/>
    <geometry>
      <mesh filename="package://bionic_biped_robot_description/meshes/ankle_link_1_1.stl" scale="0.001 0.001 0.001"/>
    </geometry>
    <material name="pa_11_nylon_hp_1130_eos_p_396_3d_"/>
  </visual>
  <collision>
    <origin xyz="0.030056 -0.048011 0.229104" rpy="0 0 0"/>
    <geometry>
      <mesh filename="package://bionic_biped_robot_description/meshes/ankle_link_1_1.stl" scale="0.001 0.001 0.001"/>
    </geometry>
  </collision>
</link>

<link name="L_bionic_biped_robot_ankle_bar_v2_1">
  <inertial>
    <origin xyz="0.022218194309809196 -0.0005483314866620015 -0.035802194593276465" rpy="0 0 0"/>
    <mass value="0.0020522771844998615"/>
    <inertia ixx="1e-06" iyy="2e-06" izz="1e-06" ixy="-0.0" iyz="0.0" ixz="1e-06"/>
  </inertial>
  <visual>
    <origin xyz="0.057018 -0.067058 0.244955" rpy="0 0 0"/>
    <geometry>
      <mesh filename="package://bionic_biped_robot_description/meshes/L_bionic_biped_robot_ankle_bar_v2_1.stl" scale="0.001 0.001 0.001"/>
    </geometry>
    <material name="pa_11_nylon_hp_1130_eos_p_396_3d_"/>
  </visual>
  <collision>
    <origin xyz="0.057018 -0.067058 0.244955" rpy="0 0 0"/>
    <geometry>
      <mesh filename="package://bionic_biped_robot_description/meshes/L_bionic_biped_robot_ankle_bar_v2_1.stl" scale="0.001 0.001 0.001"/>
    </geometry>
  </collision>
</link>

<link name="lower_link_2">
  <inertial>
    <origin xyz="-0.007328120441395017 0.005427133829352837 -0.015939198815478006" rpy="0 0 0"/>
    <mass value="0.008544769707383056"/>
    <inertia ixx="1e-06" iyy="1e-06" izz="1e-06" ixy="-0.0" iyz="-0.0" ixz="-0.0"/>
  </inertial>
  <visual>
    <origin xyz="0.004216 -0.062841 0.245489" rpy="0 0 0"/>
    <geometry>
      <mesh filename="package://bionic_biped_robot_description/meshes/lower_link_2.stl" scale="0.001 0.001 0.001"/>
    </geometry>
    <material name="pa_11_nylon_hp_1130_eos_p_396_3d_"/>
  </visual>
  <collision>
    <origin xyz="0.004216 -0.062841 0.245489" rpy="0 0 0"/>
    <geometry>
      <mesh filename="package://bionic_biped_robot_description/meshes/lower_link_2.stl" scale="0.001 0.001 0.001"/>
    </geometry>
  </collision>
</link>

<link name="leg_lower_1">
  <inertial>
    <origin xyz="0.006836110873587015 0.13624211752369741 -0.025538458001914566" rpy="0 0 0"/>
    <mass value="0.007702697584770665"/>
    <inertia ixx="2e-06" iyy="2e-06" izz="1e-06" ixy="-0.0" iyz="0.0" ixz="1e-06"/>
  </inertial>
  <visual>
    <origin xyz="0.001947 0.066869 0.262552" rpy="0 0 0"/>
    <geometry>
      <mesh filename="package://bionic_biped_robot_description/meshes/leg_lower_1.stl" scale="0.001 0.001 0.001"/>
    </geometry>
    <material name="pa_11_nylon_hp_1130_eos_p_396_3d_"/>
  </visual>
  <collision>
    <origin xyz="0.001947 0.066869 0.262552" rpy="0 0 0"/>
    <geometry>
      <mesh filename="package://bionic_biped_robot_description/meshes/leg_lower_1.stl" scale="0.001 0.001 0.001"/>
    </geometry>
  </collision>
</link>

<link name="shaft_4">
  <inertial>
    <origin xyz="-0.0012793890264828217 0.005920710613647268 -0.0005501946259371393" rpy="0 0 0"/>
    <mass value="5.79273242847201e-05"/>
    <inertia ixx="0.0" iyy="0.0" izz="0.0" ixy="0.0" iyz="0.0" ixz="-0.0"/>
  </inertial>
  <visual>
    <origin xyz="-0.019483 -0.064317 0.311042" rpy="0 0 0"/>
    <geometry>
      <mesh filename="package://bionic_biped_robot_description/meshes/shaft_4.stl" scale="0.001 0.001 0.001"/>
    </geometry>
    <material name=""/>
  </visual>
  <collision>
    <origin xyz="-0.019483 -0.064317 0.311042" rpy="0 0 0"/>
    <geometry>
      <mesh filename="package://bionic_biped_robot_description/meshes/shaft_4.stl" scale="0.001 0.001 0.001"/>
    </geometry>
  </collision>
</link>

<link name="foot_2">
  <inertial>
    <origin xyz="0.00028891292945123007 0.14287626741480924 -0.0038562114343241305" rpy="0 0 0"/>
    <mass value="0.009360295877442892"/>
    <inertia ixx="1e-06" iyy="3e-06" izz="2e-06" ixy="-0.0" iyz="-0.0" ixz="-1e-06"/>
  </inertial>
  <visual>
    <origin xyz="-0.030145 0.071766 0.309966" rpy="0 0 0"/>
    <geometry>
      <mesh filename="package://bionic_biped_robot_description/meshes/foot_2.stl" scale="0.001 0.001 0.001"/>
    </geometry>
    <material name="pa_11_nylon_hp_1130_eos_p_396_3d_"/>
  </visual>
  <collision>
    <origin xyz="-0.030145 0.071766 0.309966" rpy="0 0 0"/>
    <geometry>
      <mesh filename="package://bionic_biped_robot_description/meshes/foot_2.stl" scale="0.001 0.001 0.001"/>
    </geometry>
  </collision>
</link>

<link name="L_ankle_bar_parts_v1_1">
  <inertial>
    <origin xyz="-0.00014421668719208185 0.001995149197513729 -8.089303608793674e-06" rpy="0 0 0"/>
    <mass value="0.0005178915489442998"/>
    <inertia ixx="0.0" iyy="0.0" izz="0.0" ixy="-0.0" iyz="-0.0" ixz="0.0"/>
  </inertial>
  <visual>
    <origin xyz="0.005711 -0.066409 0.327705" rpy="0 0 0"/>
    <geometry>
      <mesh filename="package://bionic_biped_robot_description/meshes/L_ankle_bar_parts_v1_1.stl" scale="0.001 0.001 0.001"/>
    </geometry>
    <material name="pa_11_nylon_hp_1130_eos_p_396_3d_"/>
  </visual>
  <collision>
    <origin xyz="0.005711 -0.066409 0.327705" rpy="0 0 0"/>
    <geometry>
      <mesh filename="package://bionic_biped_robot_description/meshes/L_ankle_bar_parts_v1_1.stl" scale="0.001 0.001 0.001"/>
    </geometry>
  </collision>
</link>

<link name="shaft_3">
  <inertial>
    <origin xyz="-0.011438438714879722 0.13502168553881624 -0.0015977410418839266" rpy="0 0 0"/>
    <mass value="5.79273242847201e-05"/>
    <inertia ixx="0.0" iyy="0.0" izz="0.0" ixy="0.0" iyz="0.0" ixz="-0.0"/>
  </inertial>
  <visual>
    <origin xyz="-0.020577 0.065492 0.323481" rpy="0 0 0"/>
    <geometry>
      <mesh filename="package://bionic_biped_robot_description/meshes/shaft_3.stl" scale="0.001 0.001 0.001"/>
    </geometry>
    <material name=""/>
  </visual>
  <collision>
    <origin xyz="-0.020577 0.065492 0.323481" rpy="0 0 0"/>
    <geometry>
      <mesh filename="package://bionic_biped_robot_description/meshes/shaft_3.stl" scale="0.001 0.001 0.001"/>
    </geometry>
  </collision>
</link>

<link name="shaft_5">
  <inertial>
    <origin xyz="1.48955198259193e-07 3.99741982570756e-09 4.535168419694813e-07" rpy="0 0 0"/>
    <mass value="5.79273242847201e-05"/>
    <inertia ixx="0.0" iyy="0.0" izz="0.0" ixy="0.0" iyz="0.0" ixz="-0.0"/>
  </inertial>
  <visual>
    <origin xyz="-0.020577 0.065492 0.323481" rpy="0 0 0"/>
    <geometry>
      <mesh filename="package://bionic_biped_robot_description/meshes/shaft_5.stl" scale="0.001 0.001 0.001"/>
    </geometry>
    <material name=""/>
  </visual>
  <collision>
    <origin xyz="-0.020577 0.065492 0.323481" rpy="0 0 0"/>
    <geometry>
      <mesh filename="package://bionic_biped_robot_description/meshes/shaft_5.stl" scale="0.001 0.001 0.001"/>
    </geometry>
  </collision>
</link>

<joint name="„« 226" type="fixed">
  <origin xyz="-0.015186 -0.058805 0.032787" rpy="0 0 0"/>
  <parent link="base_link"/>
  <child link="R_hip_roll_xl_2"/>
</joint>

<joint name="‰ñ“] 227" type="continuous">
  <origin xyz="-0.021067 -0.015921 -0.028614" rpy="0 0 0"/>
  <parent link="R_hip_roll_xl_2"/>
  <child link="R_hip_roll_2"/>
  <axis xyz="0.996962 0.071983 0.029745"/>
</joint>

<joint name="„« 228" type="fixed">
  <origin xyz="-0.001994 -0.000144 -5.9e-05" rpy="0 0 0"/>
  <parent link="R_hip_roll_2"/>
  <child link="hip_roll_bracket_1"/>
</joint>

<joint name="„« 229" type="fixed">
  <origin xyz="-0.018402 0.012982 0.005426" rpy="0 0 0"/>
  <parent link="hip_roll_bracket_1"/>
  <child link="R_hip_yaw_xl_2"/>
</joint>

<joint name="‰ñ“] 230" type="continuous">
  <origin xyz="0.005701 -0.013968 -0.022813" rpy="0 0 0"/>
  <parent link="R_hip_yaw_xl_2"/>
  <child link="R_hip_yaw_2"/>
  <axis xyz="-0.029958 0.001887 0.999549"/>
</joint>

<joint name="„« 231" type="fixed">
  <origin xyz="6e-05 -4e-06 -0.001999" rpy="0 0 0"/>
  <parent link="R_hip_yaw_2"/>
  <child link="hip_yaw_bracket_1"/>
</joint>

<joint name="„« 232" type="fixed">
  <origin xyz="0.0192 0.007376 -0.00572" rpy="0 0 0"/>
  <parent link="hip_yaw_bracket_1"/>
  <child link="R_hip_pitch_xl_2"/>
</joint>

<joint name="‰ñ“] 233" type="continuous">
  <origin xyz="0.001803 0.011032 -0.031354" rpy="0 0 0"/>
  <parent link="R_hip_pitch_xl_2"/>
  <child link="R_hip_pitch_2"/>
  <axis xyz="0.071895 -0.997404 0.004038"/>
</joint>

<joint name="„« 234" type="fixed">
  <origin xyz="-0.000144 0.001995 -9e-06" rpy="0 0 0"/>
  <parent link="R_hip_pitch_2"/>
  <child link="hip_pitch_bracket_1"/>
</joint>

<joint name="„« 235" type="fixed">
  <origin xyz="0.01808 -0.011782 -0.012545" rpy="0 0 0"/>
  <parent link="hip_pitch_bracket_1"/>
  <child link="R_knee_xl_2"/>
</joint>

<joint name="‰ñ“] 236" type="continuous">
  <origin xyz="0.010908 0.011677 -0.034238" rpy="0 0 0"/>
  <parent link="R_knee_xl_2"/>
  <child link="R_knee_2"/>
  <axis xyz="0.071895 -0.997404 0.004038"/>
</joint>

<joint name="„« 237" type="fixed">
  <origin xyz="-0.000144 0.001995 -8e-06" rpy="0 0 0"/>
  <parent link="R_knee_2"/>
  <child link="knee_r_brecket_1"/>
</joint>

<joint name="„« 238" type="fixed">
  <origin xyz="0.013174 -0.011687 -0.025585" rpy="0 0 0"/>
  <parent link="knee_r_brecket_1"/>
  <child link="leg_upper_1"/>
</joint>

<joint name="„« 239" type="fixed">
  <origin xyz="-0.047254 -0.003763 -0.08805" rpy="0 0 0"/>
  <parent link="leg_upper_1"/>
  <child link="lower_knee_link_2"/>
</joint>

<joint name="„« 240" type="fixed">
  <origin xyz="0.0176 0.143003 -0.012338" rpy="0 0 0"/>
  <parent link="lower_knee_link_2"/>
  <child link="R_ankle_xl_2"/>
</joint>

<joint name="‰ñ“] 241" type="continuous">
  <origin xyz="-0.005237 -0.125216 -0.003583" rpy="0 0 0"/>
  <parent link="R_ankle_xl_2"/>
  <child link="R_ankle_2"/>
  <axis xyz="0.071895 -0.997404 0.004038"/>
</joint>

<joint name="„« 242" type="fixed">
  <origin xyz="-0.000144 0.001994 -8e-06" rpy="0 0 0"/>
  <parent link="R_ankle_2"/>
  <child link="ankle_link_1_2"/>
</joint>

<joint name="„« 243" type="fixed">
  <origin xyz="0.002588 -0.035907 0.000145" rpy="0 0 0"/>
  <parent link="R_ankle_2"/>
  <child link="ankle_link_2_2"/>
</joint>

<joint name="‰ñ“] 244" type="continuous">
  <origin xyz="-0.036704 0.154195 -0.016398" rpy="0 0 0"/>
  <parent link="ankle_link_2_2"/>
  <child link="R_bionic_biped_robot_ankle_bar_1"/>
  <axis xyz="0.071895 -0.997404 0.004038"/>
</joint>

<joint name="‰ñ“] 245" type="continuous">
  <origin xyz="0.06076 -0.131804 -0.082219" rpy="0 0 0"/>
  <parent link="R_bionic_biped_robot_ankle_bar_1"/>
  <child link="R_ankle_bar_parts_1"/>
  <axis xyz="-0.071895 0.997404 -0.004038"/>
</joint>

<joint name="„« 246" type="fixed">
  <origin xyz="0.022328 -0.134324 -0.019871" rpy="0 0 0"/>
  <parent link="R_ankle_xl_2"/>
  <child link="lower_link_1"/>
</joint>

<joint name="„« 247" type="fixed">
  <origin xyz="-0.005761 -0.006468 -0.017036" rpy="0 0 0"/>
  <parent link="lower_link_1"/>
  <child link="leg_lower_2"/>
</joint>

<joint name="„« 248" type="fixed">
  <origin xyz="0.019719 0.143091 -0.049065" rpy="0 0 0"/>
  <parent link="leg_lower_2"/>
  <child link="shaft_1"/>
</joint>

<joint name="‰ñ“] 249" type="continuous">
  <origin xyz="0.010518 -0.134087 0.001069" rpy="0 0 0"/>
  <parent link="shaft_1"/>
  <child link="foot_1"/>
  <axis xyz="-0.071895 0.997404 -0.004038"/>
</joint>

<joint name="„« 270" type="fixed">
  <origin xyz="-0.023814 0.060884 0.032303" rpy="0 0 0"/>
  <parent link="base_link"/>
  <child link="L_hip_roll_xl_2"/>
</joint>

<joint name="‰ñ“] 271" type="continuous">
  <origin xyz="-0.023116 0.012504 -0.028729" rpy="0 0 0"/>
  <parent link="L_hip_roll_xl_2"/>
  <child link="L_hip_roll_2"/>
  <axis xyz="0.996962 0.071983 0.029745"/>
</joint>

<joint name="„« 272" type="fixed">
  <origin xyz="-0.001993 -0.000144 -6e-05" rpy="0 0 0"/>
  <parent link="L_hip_roll_2"/>
  <child link="hip_roll_bracket_2"/>
</joint>

<joint name="„« 273" type="fixed">
  <origin xyz="-0.005677 -0.163558 0.006141" rpy="0 0 0"/>
  <parent link="hip_roll_bracket_2"/>
  <child link="L_hip_yow_xl_2"/>
</joint>

<joint name="‰ñ“] 274" type="continuous">
  <origin xyz="-0.007024 0.162572 -0.023527" rpy="0 0 0"/>
  <parent link="L_hip_yow_xl_2"/>
  <child link="L_hip_yow_2"/>
  <axis xyz="-0.029958 0.001887 0.999549"/>
</joint>

<joint name="„« 275" type="fixed">
  <origin xyz="6e-05 -3e-06 -0.001999" rpy="0 0 0"/>
  <parent link="L_hip_yow_2"/>
  <child link="hip_yaw_bracket_2"/>
</joint>

<joint name="„« 276" type="fixed">
  <origin xyz="0.030739 -0.152707 -0.005072" rpy="0 0 0"/>
  <parent link="hip_yaw_bracket_2"/>
  <child link="L_hip_pitch_xl_2"/>
</joint>

<joint name="‰ñ“] 277" type="continuous">
  <origin xyz="-0.007292 0.137203 -0.031866" rpy="0 0 0"/>
  <parent link="L_hip_pitch_xl_2"/>
  <child link="L_hip_pitch_2"/>
  <axis xyz="-0.071895 0.997404 -0.004038"/>
</joint>

<joint name="„« 278" type="fixed">
  <origin xyz="0.000144 -0.001995 8e-06" rpy="0 0 0"/>
  <parent link="L_hip_pitch_2"/>
  <child link="hip_pitch_bracket_2"/>
</joint>

<joint name="„« 279" type="fixed">
  <origin xyz="0.026886 -0.133963 -0.012051" rpy="0 0 0"/>
  <parent link="hip_pitch_bracket_2"/>
  <child link="L_knee_xl_2"/>
</joint>

<joint name="‰ñ“] 280" type="continuous">
  <origin xyz="0.001814 0.137848 -0.034749" rpy="0 0 0"/>
  <parent link="L_knee_xl_2"/>
  <child link="L_knee_2"/>
  <axis xyz="-0.071895 0.997404 -0.004038"/>
</joint>

<joint name="„« 281" type="fixed">
  <origin xyz="0.000143 -0.001995 8e-06" rpy="0 0 0"/>
  <parent link="L_knee_2"/>
  <child link="knee_l_bracket_1"/>
</joint>

<joint name="„« 282" type="fixed">
  <origin xyz="0.011377 0.013248 -0.025685" rpy="0 0 0"/>
  <parent link="knee_l_bracket_1"/>
  <child link="leg_upper_2"/>
</joint>

<joint name="„« 283" type="fixed">
  <origin xyz="-0.037512 -0.138911 -0.087503" rpy="0 0 0"/>
  <parent link="leg_upper_2"/>
  <child link="lower_knee_link_1"/>
</joint>

<joint name="„« 284" type="fixed">
  <origin xyz="0.018462 0.131034 -0.01229" rpy="0 0 0"/>
  <parent link="lower_knee_link_1"/>
  <child link="L_ankle_xl_2"/>
</joint>

<joint name="‰ñ“] 285" type="continuous">
  <origin xyz="-0.013396 -0.012011 -0.004041" rpy="0 0 0"/>
  <parent link="L_ankle_xl_2"/>
  <child link="L_ankle_2"/>
  <axis xyz="-0.071895 0.997404 -0.004038"/>
</joint>

<joint name="„« 286" type="fixed">
  <origin xyz="-0.002589 0.035907 -0.000145" rpy="0 0 0"/>
  <parent link="L_ankle_2"/>
  <child link="ankle_link_2_1"/>
</joint>

<joint name="„« 287" type="fixed">
  <origin xyz="0.000143 -0.001995 8e-06" rpy="0 0 0"/>
  <parent link="L_ankle_2"/>
  <child link="ankle_link_1_1"/>
</joint>

<joint name="‰ñ“] 288" type="continuous">
  <origin xyz="-0.02423 -0.018855 -0.015698" rpy="0 0 0"/>
  <parent link="ankle_link_2_1"/>
  <child link="L_bionic_biped_robot_ankle_bar_v2_1"/>
  <axis xyz="-0.071895 0.997404 -0.004038"/>
</joint>

<joint name="„« 289" type="fixed">
  <origin xyz="0.012587 0.000824 -0.020418" rpy="0 0 0"/>
  <parent link="L_ankle_xl_2"/>
  <child link="lower_link_2"/>
</joint>

<joint name="„« 290" type="fixed">
  <origin xyz="0.002269 -0.12971 -0.017063" rpy="0 0 0"/>
  <parent link="lower_link_2"/>
  <child link="leg_lower_1"/>
</joint>

<joint name="„« 291" type="fixed">
  <origin xyz="0.02143 0.131186 -0.04849" rpy="0 0 0"/>
  <parent link="leg_lower_1"/>
  <child link="shaft_4"/>
</joint>

<joint name="‰ñ“] 292" type="continuous">
  <origin xyz="0.010662 -0.136083 0.001076" rpy="0 0 0"/>
  <parent link="shaft_4"/>
  <child link="foot_2"/>
  <axis xyz="-0.071895 0.997404 -0.004038"/>
</joint>

<joint name="‰ñ“] 294" type="continuous">
  <origin xyz="0.051307 -0.000649 -0.08275" rpy="0 0 0"/>
  <parent link="L_bionic_biped_robot_ankle_bar_v2_1"/>
  <child link="L_ankle_bar_parts_v1_1"/>
  <axis xyz="-0.071895 0.997404 -0.004038"/>
</joint>

<joint name="„« 295" type="fixed">
  <origin xyz="-0.009568 0.006274 -0.013515" rpy="0 0 0"/>
  <parent link="foot_2"/>
  <child link="shaft_3"/>
</joint>

<joint name="„« 296" type="fixed">
  <origin xyz="-0.008562 -0.00769 -0.013459" rpy="0 0 0"/>
  <parent link="foot_1"/>
  <child link="shaft_5"/>
</joint>

</robot>
